Workbook

Sheet LEIA-ME
A1: M1 — Modelo comparativo das quatro vias
B4: Identificação
B5: Projeto: Dra. Júlia Best (NIF 272180610) — cliente faturável: Gerir Saúde.
B6: Origem: ata de 18/08/2026 (MOD COO 007/1). Brief de entregáveis de 22/08/2026.
B7: Estatuto: ENTREGÁVEL INTERNO. Não sai para a cliente — a entrega do ficheiro está expressamente fora de âmbito (secção 5 do brief). O que sai são as tabelas do capítulo 3 e do anexo E2, sem fórmulas visíveis.
B8: Propriedade: ativo reutilizável VCLevel.
B9: Estado atual — ler antes de usar
B10: A cliente não forneceu nenhum dos oito inputs da secção 4 do brief. Todos os valores da folha Inputs são placeholders para testar o motor de cálculo.
B11: Nenhum número deste ficheiro pode ser citado no relatório, no deck ou perante a cliente antes de (i) os inputs reais entrarem, (ii) a folha Parâmetros ser confirmada para 2026 pela equipa de Fiscalidade, e (iii) a folha Validação estar assinada.
B12: Como está organizado
B13: Parâmetros — todas as taxas, escalões e limiares, cada um com a norma e o estado de validação. Nenhuma taxa é escrita dentro de uma fórmula noutra folha.
B14: Operacao — camada operacional: gabinetes, dias, duração da consulta, preço e utilização. É daqui que sai a faturação quando FONTE_FAT = 2. A linha de utilização diz se a projeção cabe fisicamente no espaço.
B15: Inputs — folha única de parâmetros do caso, em três cenários de faturação. Contém a alavanca MOD_COLAB, que alterna entre os dois modelos de colaboração da ata (1 = prestação de serviços, 2 = cedência de sala) e reconfigura toda a estrutura de receita e custo.
... B47: Este ficheiro é gerado por build_m1.py. Alterações estruturais fazem-se no script e regenera-se; alterações de valores fazem-se nas células amarelas.

Sheet Parametros
A1: M1 — Parâmetros fiscais e contributivos
A2: Todos os parâmetros do modelo vivem aqui. Nenhuma folha de cálculo pode conter uma taxa escrita dentro de uma fórmula. Coluna E indica o estado de validação pela equipa de Fiscalidade.
A4: Parâmetro | B4: Referência | C4: Valor | D4: Fonte normativa | E4: Estado de validação | F4: Por validar
A5: Segurança Social
A6: Indexante dos Apoios Sociais (mensal) | B6: IAS | C6: 522.5 | D6: Portaria de atualização anual do IAS | E6: A ATUALIZAR PARA 2026 | F6: 1
A7: TI — % da prestação de serviços que forma o rendimento relevante | B7: SS_TI_PCT | C7: 0.7 | D7: Art. 162.º n.º 1 Cód. Contributivo | E7: Confirmar | F7: 0
A8: TI — taxa contributiva | B8: SS_TI_TAXA | C8: 0.214 | D8: Art. 168.º n.º 1 Cód. Contributivo | E8: Confirmar | F8: 0
A9: TI — teto da base de incidência mensal (múltiplo do IAS) | B9: SS_TI_TETO | C9: 12 | D9: Art. 163.º n.º 2 Cód. Contributivo | E9: Confirmar | F9: 0
A10: TI — contribuição mensal mínima | B10: SS_TI_MIN | C10: 20 | D10: Regime dos trabalhadores independentes | E10: Confirmar | F10: 0
A11: MOE/gerência — taxa a cargo da entidade | B11: SS_MOE_ENT | C11: 0.2375 | D11: Art. 63.º e 168.º Cód. Contributivo | E11: CONFIRMAR (ver R1-12) | F11: 1
A12: MOE/gerência — taxa a cargo do beneficiário | B12: SS_MOE_BEN | C12: 0.11 | D12: Art. 63.º e 168.º Cód. Contributivo | E12: CONFIRMAR (ver R1-12) | F12: 1
A13: MOE — base de incidência mínima (múltiplo do IAS) | B13: SS_MOE_MIN | C13: 1 | D13: Art. 166.º Cód. Contributivo | E13: Confirmar | F13: 0
A14: Trabalhador por conta de outrem — taxa a cargo da entidade empregadora | B14: TSU_ENT | C14: 0.2375 | D14: Art. 53.º Cód. Contributivo | E14: Confirmar | F14: 0
A15: Trabalhador por conta de outrem — taxa a cargo do trabalhador | B15: TSU_TRAB | C15: 0.11 | D15: Art. 53.º Cód. Contributivo | E15: Confirmar | F15: 0
A16: Prazo de prescrição das contribuições (anos) | B16: PRESCR | C16: 5 | D16: Art. 187.º Cód. Contributivo | E16: CONFIRMAR (ver R1-37) | F16: 1
A17: Taxa anual de juros de mora aplicada às contribuições em falta | B17: JUROS_MORA | C17: 0.05 | D17: Regime dos juros de mora de dívidas ao Estado | E17: CONFIRMAR taxa em vigor | F17: 1
A18: Coima estimada, em % das contribuições devidas pela entidade | B18: COIMA_PCT | C18: 0.5 | D18: Moldura das contraordenações do Cód. Contributivo | E18: ESTIMATIVA GROSSEIRA — ver R1-38 | F18: 0
A19: Limiares operacionais de alerta
A20: Utilização acima da qual a projeção é impossível | B20: UTIL_MAX | C20: 1 | D20: Definição do modelo | E20: Validado | F20: 0
A21: Utilização acima da qual a operação é muito exigente | B21: UTIL_ALTA | C21: 0.85 | D21: Convenção de trabalho VCLevel | E21: Decisão de equipa | F21: 0
A22: Utilização abaixo da qual o espaço está subaproveitado | B22: UTIL_BAIXA | C22: 0.3 | D22: Convenção de trabalho VCLevel | E22: Decisão de equipa | F22: 0
A23: IRS — categoria B e regras de determinação
A24: Coeficiente do regime simplificado (atividades do art. 151.º) | B24: COEF | C24: 0.75 | D24: Art. 31.º n.º 1 al. b) CIRS — fisioterapeutas constam da tabela do art. 151.º | E24: Validado | F24: 0
A25: Limiar de justificação de despesas | B25: LIM_JUST | C25: 0.15 | D25: Art. 31.º n.º 13 CIRS | E25: Validado | F25: 0
A26: Dedução específica considerada na justificação de despesas | B26: DED_ESP | C26: 4104 | D26: Art. 31.º n.º 13 al. a) CIRS | E26: Confirmar valor em vigor | F26: 0
A27: Contribuições SS — dedutíveis na parte que excede esta % do rendimento bruto | B27: LIM_CONTRIB | C27: 0.1 | D27: Art. 31.º n.º 2 CIRS | E27: Confirmar | F27: 0
A28: Limiar de permanência no regime simplificado (rendimento bruto) | B28: LIM_SIMPL | C28: 200000 | D28: Art. 28.º n.º 2 CIRS | E28: Confirmar | F28: 0
A29: Período mínimo de permanência na opção por contabilidade organizada (anos) | B29: PERM_OPCAO | C29: 3 | D29: Art. 28.º n.º 5 CIRS | E29: Confirmar | F29: 0
A30: Dedução específica da categoria A | B30: DED_CATA | C30: 4104 | D30: Art. 25.º n.º 1 al. a) CIRS | E30: Confirmar valor em vigor | F30: 0
A31: Coeficiente do simplificado aplicável à receita de cedência de espaço | B31: COEF_SALA | C31: 0.35 | D31: Art. 31.º n.º 1 al. c) CIRS — restantes prestações de serviços | E31: CONFIRMAR (ver R1-29). Depende de N1-04 | F31: 1
A32: IRC e tributação da distribuição
A33: IRC — taxa aplicável ao primeiro escalão (PME) | B33: IRC_PME | C33: 0.16 | D33: Art. 87.º n.º 2 CIRC | E33: CONFIRMAR TAXA 2026 (ver R1-11) | F33: 1
A34: IRC — limite da matéria coletável do primeiro escalão | B34: IRC_LIM | C34: 50000 | D34: Art. 87.º n.º 2 CIRC | E34: CONFIRMAR 2026 | F34: 1
A35: IRC — taxa geral | B35: IRC_GER | C35: 0.2 | D35: Art. 87.º n.º 1 CIRC | E35: CONFIRMAR TAXA 2026 (ver R1-11) | F35: 1
A36: Derrama municipal (município do Porto) | B36: DERRAMA | C36: 0.015 | D36: Art. 18.º Lei 73/2013 + deliberação municipal | E36: CONFIRMAR município e isenção PME | F36: 1
A37: Derrama incide sobre sociedade transparente? (1=sim / 0=não) | B37: DERR_TRANSP | C37: 0 | D37: Questão controvertida — art. 12.º CIRC vs. art. 18.º Lei 73/2013 | E37: EM ABERTO (ver R1-13) | F37: 1
A38: Dividendos — taxa liberatória | B38: DIV_LIB | C38: 0.28 | D38: Art. 71.º n.º 1 CIRS | E38: Confirmar | F38: 0
A39: Dividendos — % considerada em caso de englobamento | B39: DIV_ENG | C39: 0.5 | D39: Art. 40.º-A n.º 1 CIRS | E39: Confirmar | F39: 0
A40: IVA
A41: IVA — taxa normal (continente) | B41: IVA_NORM | C41: 0.23 | D41: Art. 18.º n.º 1 al. c) CIVA | E41: Validado | F41: 0
...

Sheet Operacao
A1: M1 — Camada operacional: capacidade, utilização e faturação
A2: A faturação deixa de ser um palpite e passa a ser uma consequência. Gabinetes, dias de funcionamento, duração da consulta e preço determinam quanto é possível faturar — e a linha de utilização diz se a projeção cabe no espaço. Uma projeção que exija mais de 100% de utilização é impossível, não é otimista.
A4: Rubrica | B4: Ref. | C4: Baixo | D4: Base | E4: Alto | F4: Nota
A5: Espaço e horário
A6: N.º de gabinetes | B6: N_GAB | C6: 2 | D6: 2 | E6: 3 | F6: Input cliente 3 — EM FALTA. Ata, ponto 3: dois espaços em avaliação, 2 e 3 gabinetes. A comparação dedicada está na folha Espaco.
A7: Dias de funcionamento por ano | B7: DIAS_ANO | C7: 220 | D7: 220 | E7: 220 | F7: EM FALTA. 220 dias corresponde a semana de 5 dias com férias e feriados.
A8: Horas úteis por gabinete por dia | B8: HORAS_DIA | C8: 8 | D8: 8 | E8: 8 | F8: EM FALTA.
A9: Duração média da consulta (minutos) | B9: DUR_CONS | C9: 45 | D9: 45 | E9: 45 | F9: EM FALTA. Determina a capacidade. Sessões de 30 ou de 60 minutos mudam tudo o que vem abaixo.
A10: Atividade da Dra. Júlia
A11: Dias por ano em que atende | B11: DIAS_JUL | C11: 190 | D11: 200 | E11: 210 | F11: EM FALTA.
A12: Consultas por dia | B12: CONS_JUL | C12: 5 | D12: 6 | E12: 7 | F12: EM FALTA.
A13: Preço médio por consulta | B13: PRECO_JUL | C13: 45 | D13: 48 | E13: 50 | F13: Input cliente 2 — EM FALTA. Sai da tabela de preços, que a ata regista como inexistente.
A14: Fisioterapeutas a integrar
A15: N.º de fisioterapeutas | B15: N_FISIO | C15: 1 | D15: 1 | E15: 2 | F15: Ata, ponto 3.
A16: Dias por ano, por profissional | B16: DIAS_FIS | C16: 160 | D16: 180 | E16: 180 | F16: EM FALTA.
A17: Consultas por dia, por profissional | B17: CONS_FIS | C17: 4 | D17: 5 | E17: 4 | F17: EM FALTA.
A18: Preço médio por consulta | B18: PRECO_FIS | C18: 45 | D18: 48 | E18: 50 | F18: EM FALTA.
A19: Capacidade
A20: Capacidade diária por gabinete (consultas) | B20: CAP_DIA | C20: =$C$8*60/$C$9 | D20: =$D$8*60/$D$9 | E20: =$E$8*60/$E$9
A21: Capacidade anual instalada (consultas) | B21: CAP_ANO | C21: =$C$6*$C$7*$C$20 | D21: =$D$6*$D$7*$D$20 | E21: =$E$6*$E$7*$E$20
A22: Procura projetada
A23: Consultas anuais da Dra. Júlia | B23: CONS_JUL_A | C23: =$C$11*$C$12 | D23: =$D$11*$D$12 | E23: =$E$11*$E$12
A24: Consultas anuais dos colaboradores | B24: CONS_FIS_A | C24: =$C$15*$C$16*$C$17 | D24: =$D$15*$D$16*$D$17 | E24: =$E$15*$E$16*$E$17
A25: Consultas anuais totais | B25: CONS_TOT | C25: =$C$23+$C$24 | D25: =$D$23+$D$24 | E25: =$E$23+$E$24
A26: TAXA DE UTILIZAÇÃO DOS GABINETES | B26: UTILIZ | C26: =IF($C$21<=0,0,$C$25/$C$21) | D26: =IF($D$21<=0,0,$D$25/$D$21) | E26: =IF($E$21<=0,0,$E$25/$E$21) | F26: Acima de 100% a projeção é impossível: não há gabinetes para as consultas previstas. Acima de 85% é operacionalmente muito exigente. Ver folha Alertas.
A27: Leitura da utilização | B27: TESTE_CAP | C27: =IF($C$26>Parametros!$C$20,"IMPOSSÍVEL — a projeção não cabe no espaço",IF($C$26>Parametros!$C$21,"MUITO EXIGENTE — pouca folga operacional",IF($C$26<Parametros!$C$22,"FOLGA ELEVADA — capacidade subaproveitada","PLAUSÍVEL"))) | D27: =IF($D$26>Parametros!$C$20,"IMPOSSÍVEL — a projeção não cabe no espaço",IF($D$26>Parametros!$C$21,"MUITO EXIGENTE — pouca folga operacional",IF($D$26<Parametros!$C$22,"FOLGA ELEVADA — capacidade subaproveitada","PLAUSÍVEL"))) | E27: =IF($E$26>Parametros!$C$20,"IMPOSSÍVEL — a projeção não cabe no espaço",IF($E$26>Parametros!$C$21,"MUITO EXIGENTE — pouca folga operacional",IF($E$26<Parametros!$C$22,"FOLGA ELEVADA — capacidade subaproveitada","PLAUSÍVEL")))
A28: Faturação derivada
A29: Faturação anual da Dra. Júlia | B29: FAT_JUL | C29: =$C$23*$C$13 | D29: =$D$23*$D$13 | E29: =$E$23*$E$13
A30: Faturação anual gerada pelos colaboradores | B30: FAT_FIS | C30: =$C$24*$C$18 | D30: =$D$24*$D$18 | E30: =$E$24*$E$18
A31: Faturação anual total gerada | B31: FAT_TOT | C31: =$C$29+$C$30 | D31: =$D$29+$D$30 | E31: =$E$29+$E$30
A32: Unit economics
A33: Faturação por gabinete | B33: FAT_GAB | C33: =IF($C$6<=0,0,$C$31/$C$6) | D33: =IF($D$6<=0,0,$D$31/$D$6) | E33: =IF($E$6<=0,0,$E$31/$E$6)
A34: Consultas por gabinete | B34: CONS_GAB | C34: =IF($C$6<=0,0,$C$25/$C$6) | D34: =IF($D$6<=0,0,$D$25/$D$6) | E34: =IF($E$6<=0,0,$E$25/$E$6)
A35: Faturação por profissional | B35: FAT_PROF | C35: =$C$31/(1+$C$15) | D35: =$D$31/(1+$D$15) | E35: =$E$31/(1+$E$15)
A36: Faturação por hora de gabinete disponível | B36: FAT_HORA | C36: =IF($C$6*$C$7*$C$8<=0,0,$C$31/($C$6*$C$7*$C$8)) | D36: =IF($D$6*$D$7*$D$8<=0,0,$D$31/($D$6*$D$7*$D$8)) | E36: =IF($E$6*$E$7*$E$8<=0,0,$E$31/($E$6*$E$7*$E$8)) | F36: Indicador de eficiência do espaço, independente da estrutura fiscal.

Sheet Inputs
A1: M1 — Inputs (folha única de parâmetros do caso)
A2: ATENÇÃO: à data de 22/08/2026 a cliente não forneceu nenhum dos inputs da secção 4 do brief. Todos os valores abaixo são ILUSTRATIVOS, servem apenas para testar o motor de cálculo, e estão registados como pressupostos em R1. Nenhum número desta folha pode transitar para o relatório enquanto não for substituído por dados da cliente.
A4: Input | B4: Referência | C4: Baixo | D4: Base | E4: Alto | F4: Nota / origem | G4: Tipo | H4: Fonte | I4: Confiança
A5: Faturação — origem e modelo de colaboração
A6: ORIGEM DA FATURAÇÃO: 1 = valores manuais · 2 = derivada da capacidade (folha Operacao) | B6: FONTE_FAT | C6: 2 | D6: 2 | E6: 2 | F6: ALAVANCA. Em 2, a faturação é uma consequência de gabinetes, dias, duração e preço, e é verificável contra a capacidade instalada. Em 1, é um número que alguém escreveu. | G6: ESTIMATIVA_VCLEVEL | H6: VCLevel | I6: Alta | J6: 0
A7: Faturação anual da Dra. Júlia — valor manual | B7: FAT_PROP_MAN | C7: 52000 | D7: 65000 | E7: 85000 | F7: Só usado se FONTE_FAT = 1. | G7: A_VALIDAR | H7: cliente | I7: Baixa | J7: 1
A8: Faturação dos colaboradores — valor manual | B8: FAT_COLAB_MAN | C8: 18000 | D8: 30000 | E8: 45000 | F8: Só usado se FONTE_FAT = 1. | G8: A_VALIDAR | H8: cliente | I8: Baixa | J8: 1
A9: Faturação anual da própria Dra. Júlia (isenta, art. 9.º CIVA) | B9: FAT_PROP | C9: =IF(Inputs!$C$6=1,Inputs!$C$7,Operacao!$C$29) | D9: =IF(Inputs!$D$6=1,Inputs!$D$7,Operacao!$D$29) | E9: =IF(Inputs!$E$6=1,Inputs!$E$7,Operacao!$E$29) | F9: Doentes próprios, independentemente do modelo de colaboração. | G9: DERIVADO | H9: modelo | I9: n/a | J9: 0
A10: Faturação anual gerada pelos fisioterapeutas a integrar | B10: FAT_COLAB | C10: =IF(Inputs!$C$6=1,Inputs!$C$8,Operacao!$C$30) | D10: =IF(Inputs!$D$6=1,Inputs!$D$8,Operacao!$D$30) | E10: =IF(Inputs!$E$6=1,Inputs!$E$8,Operacao!$E$30) | F10: No modelo 1 é faturada pela clínica; no modelo 2 é faturada diretamente pelos profissionais e nunca passa pela clínica. | G10: DERIVADO | H10: modelo | I10: n/a | J10: 0
A11: MODELO DE COLABORAÇÃO: 1 = prestação de serviços · 2 = cedência de sala | B11: MOD_COLAB | C11: 1 | D11: 1 | E11: 1 | F11: ALAVANCA. Ata, ponto 4. Alterna toda a estrutura de receita e custo. Sustenta a exposição E2.6. AVISO: a qualificação jurídica e fiscal depende da configuração contratual e operacional concreta, não do nome comercial do modelo. Ver N1-04 e R1-31. | G11: A_VALIDAR | H11: cliente | I11: Baixa | J11: 1
A12: Modelo 1 — honorários em % da faturação que o colaborador gera | B12: PCT_HONOR | C12: 0.7 | D12: 0.7 | E12: 0.7 | F12: Input cliente 5 — EM FALTA. Variável de sensibilidade: é o que separa faturação de margem. | G12: A_VALIDAR | H12: cliente | I12: Baixa | J12: 1
A13: Modelo 1 — honorários anuais a pagar aos fisioterapeutas | B13: HONOR | C13: =Inputs!$C$10*Inputs!$C$12 | D13: =Inputs!$D$10*Inputs!$D$12 | E13: =Inputs!$E$10*Inputs!$E$12 | F13: Ignorado no modelo 2. | G13: DERIVADO | H13: modelo | I13: n/a | J13: 0
A14: Modelo 2 — renda em % da faturação que o colaborador gera | B14: PCT_SALA | C14: 0.3 | D14: 0.3 | E14: 0.3 | F14: Input cliente 5 — EM FALTA. Se a renda for fixa e não percentual, introduzir o valor equivalente. | G14: A_VALIDAR | H14: cliente | I14: Baixa | J14: 1
A15: Modelo 2 — receita anual de cedência de sala | B15: REC_SALA | C15: =Inputs!$C$10*Inputs!$C$14 | D15: =Inputs!$D$10*Inputs!$D$14 | E15: =Inputs!$E$10*Inputs!$E$14 | F15: Ignorado no modelo 1. | G15: DERIVADO | H15: modelo | I15: n/a | J15: 0
A16: Cedência de sala sujeita a IVA? (1 = sim / 0 = arrendamento isento) | B16: SALA_TRIB | C16: 0 | D16: 0 | E16: 0 | F16: Depende de N1-04: arrendamento isento (art. 9.º n.º 29 CIVA) ou prestação de serviços com disponibilização de meios, tributada. Não está resolvido. | G16: A_VALIDAR | H16: legislação | I16: Baixa | J16: 1
A17: Faturação anual sujeita a IVA dentro da sociedade (atividade do cônjuge) | B17: FAT_TRIB | C17: 0 | D17: 0 | E17: 0 | F17: Input cliente 6 — EM FALTA. Só relevante na via 4 e no cenário de sujeito passivo misto. | G17: A_VALIDAR | H17: cliente | I17: Baixa | J17: 1
A18: Custos operacionais anuais
A19: Renda do espaço | B19: RENDA | C19: 12000 | D19: 14400 | E19: 18000 | F19: Input cliente 3 — EM FALTA. Baixo/Base = 2 gabinetes; Alto = 3 gabinetes. | G19: A_VALIDAR | H19: contrato | I19: Baixa | J19: 1
A20: Condomínio e encargos do espaço | B20: CONDOM | C20: 1200 | D20: 1500 | E20: 1800 | F20: Input cliente 3 — EM FALTA. | G20: A_VALIDAR | H20: contrato | I20: Baixa | J20: 1
A21: Seguros (RC profissional, multirriscos) | B21: SEGUROS | C21: 900 | D21: 1100 | E21: 1400 | F21: EM FALTA. | G21: ESTIMATIVA_VCLEVEL | H21: VCLevel | I21: Baixa | J21: 0
A22: Software de gestão e faturação | B22: SOFTW | C22: 600 | D22: 900 | E22: 1200 | F22: EM FALTA. | G22: ESTIMATIVA_VCLEVEL | H22: VCLevel | I22: Baixa | J22: 0
A23: Consumíveis clínicos, em % da faturação da estrutura | B23: PCT_CONSUM | C23: 0.03 | D23: 0.03 | E23: 0.03 | F23: EM FALTA. Modelado como custo variável, o que é necessário para o break-even operacional. | G23: ESTIMATIVA_VCLEVEL | H23: benchmark | I23: Média | J23: 0
A24: Consumíveis clínicos | B24: CONSUM | C24: =(Inputs!$C$9+IF(Inputs!$C$11=1,Inputs!$C$10,0))*Inputs!$C$23 | D24: =(Inputs!$D$9+IF(Inputs!$D$11=1,Inputs!$D$10,0))*Inputs!$D$23 | E24: =(Inputs!$E$9+IF(Inputs!$E$11=1,Inputs!$E$10,0))*Inputs!$E$23 | F24: Custo variável: acompanha as consultas realizadas dentro da estrutura. | G24: DERIVADO | H24: modelo | I24: n/a | J24: 0
A25: Outros custos operacionais | B25: OUTROS | C25: 1500 | D25: 2000 | E25: 2500 | F25: EM FALTA. | G25: ESTIMATIVA_VCLEVEL | H25: VCLevel | I25: Baixa | J25: 0
A26: Investimento inicial (valores sem IVA)
A27: Obras e adaptação do espaço | B27: INV_OBRAS | C27: 15000 | D27: 25000 | E27: 40000 | F27: Input cliente 4 — EM FALTA. | G27: A_VALIDAR | H27: orçamento | I27: Baixa | J27: 1
A28: Equipamento clínico à taxa normal | B28: INV_EQUIP | C28: 12000 | D28: 20000 | E28: 30000 | F28: Input cliente 4 — EM FALTA. | G28: A_VALIDAR | H28: orçamento | I28: Baixa | J28: 1
A29: Equipamento clínico elegível para taxa reduzida | B29: INV_EQUIP_R | C29: 0 | D29: 0 | E29: 0 | F29: A confirmar contra as verbas 2.5 e 2.6 da Lista I do CIVA. Se houver elegibilidade, reduz a base do problema de IVA. | G29: A_VALIDAR | H29: legislação | I29: Baixa | J29: 1
A30: Software e sistemas | B30: INV_SOFT | C30: 1500 | D30: 2000 | E30: 3000 | F30: EM FALTA. | G30: A_VALIDAR | H30: orçamento | I30: Baixa | J30: 1
A31: Vias societárias (3 e 4)
A32: Remuneração anual bruta de gerência | B32: REM_GER | C32: 14000 | D32: 16800 | E32: 20000 | F32: Variável de decisão, não dado da cliente. Testar sensibilidade. | G32: ESTIMATIVA_VCLEVEL | H32: VCLevel | I32: Média | J32: 0
A33: Tributações autónomas estimadas (anual) | B33: TA_EST | C33: 500 | D33: 800 | E33: 1200 | F33: A quantificar pela Fiscalidade em função de viatura e despesas de representação. | G33: ESTIMATIVA_VCLEVEL | H33: VCLevel | I33: Baixa | J33: 0
A34: Política de distribuição de resultados (% do lucro após imposto) | B34: POL_DIST | C34: 1 | D34: 1 | E34: 1 | F34: ALAVANCA. Testar 0% / 50% / 100% — é aqui que se decide se afastar a transparência compensa. | G34: A_VALIDAR | H34: cliente | I34: Baixa | J34: 1
A35: % do capital social detida pelo cônjuge | B35: PCT_CONJ | C35: 0.26 | D35: 0.26 | E35: 0.26 | F35: Só via 4. Tem de exceder 25% para afastar o teste de capital do art. 6.º n.º 4 al. b) ii) CIRC. Ver N1. | G35: ESTIMATIVA_VCLEVEL | H35: VCLevel | I35: Média | J35: 0
A36: Agregado familiar (IRS)
A37: Rendimento anual do cônjuge fora da estrutura (líquido de deduções específicas) | B37: REND_CONJ | C37: 14000 | D37: 18000 | E37: 22000 | F37: Input cliente 6 e 7 — EM FALTA. | G37: A_VALIDAR | H37: cliente | I37: Baixa | J37: 1
A38: Opção por tributação conjunta (1 = sim / 0 = não) | B38: CONJUNTA | C38: 1 | D38: 1 | E38: 1 | F38: Input cliente 7 — EM FALTA. | G38: A_VALIDAR | H38: cliente | I38: Baixa | J38: 1
A39: N.º de dependentes | B39: N_DEP | C39: 0 | D39: 0 | E39: 0 | F39: Input cliente 7 — EM FALTA. | G39: A_VALIDAR | H39: cliente | I39: Baixa | J39: 1
A40: Deduções à coleta estimadas do agregado | B40: DED_COL | C40: 500 | D40: 500 | E40: 500 | F40: EM FALTA. Não afeta a comparação entre vias (cancela-se no diferencial), afeta o IRS total. | G40: ESTIMATIVA_VCLEVEL | H40: VCLevel | I40: Baixa | J40: 0
A41: Derivadas — não preencher, calculam-se a partir do modelo de colaboração
...

Sheet V1_ENI_Simplificado
A1: Via 1 — ENI, regime simplificado (situação atual)
A2: Enquadramento atual da cliente (ata, ponto 2). O ponto em teste é o do art. 31.º n.º 13 CIRS: com custos reais elevados, o coeficiente deixa de cobrir as despesas e ainda há acréscimo por insuficiência de justificação.
A4: Rubrica | B4: Ref. | C4: Baixo | D4: Base | E4: Alto | F4: Nota / norma
A5: Categoria B — regime simplificado
A6: Faturação isenta (fisioterapia) | B6: FAT | C6: =Inputs!$C$42 | D6: =Inputs!$D$42 | E6: =Inputs!$E$42
A7: Receita de cedência de espaço | B7: REC_S | C7: =Inputs!$C$43 | D7: =Inputs!$D$43 | E7: =Inputs!$E$43 | F7: Zero no modelo de prestação de serviços. Ver a alavanca MOD_COLAB na folha Inputs.
A8: Rendimento bruto total da categoria B | B8: RB_TOT | C8: =$C$6+$C$7 | D8: =$D$6+$D$7 | E8: =$E$6+$E$7
A9: Coeficiente aplicável à fisioterapia | B9: COEF | C9: =Parametros!$C$24 | D9: =Parametros!$C$24 | E9: =Parametros!$C$24 | F9: Art. 31.º n.º 1 al. b) CIRS. Fisioterapeutas constam da tabela do art. 151.º — o coeficiente 0,35 não é aplicável a esta parcela.
A10: Coeficiente aplicável à cedência de espaço | B10: COEF_S | C10: =Parametros!$C$31 | D10: =Parametros!$C$31 | E10: =Parametros!$C$31 | F10: Coeficiente distinto, e por confirmar (R1-29). Depende de a cedência ser qualificada como prestação de serviços ou como rendimento predial — N1-04.
A11: Rendimento tributável pelos coeficientes | B11: RT_COEF | C11: =$C$6*$C$9+$C$7*$C$10 | D11: =$D$6*$D$9+$D$7*$D$10 | E11: =$E$6*$E$9+$E$7*$E$10
A12: Limiar de justificação de despesas (15% do rendimento bruto) | B12: LIMIAR | C12: =$C$8*Parametros!$C$25 | D12: =$D$8*Parametros!$C$25 | E12: =$E$8*Parametros!$C$25 | F12: Art. 31.º n.º 13 CIRS.
A13: Despesas justificáveis — dedução específica | B13: D_ESP | C13: =Parametros!$C$26 | D13: =Parametros!$C$26 | E13: =Parametros!$C$26
A14: Despesas justificáveis — rendas do imóvel afeto | B14: D_RENDA | C14: =Inputs!$C$19 | D14: =Inputs!$D$19 | E14: =Inputs!$E$19 | F14: Art. 31.º n.º 13 al. c) CIRS.
A15: Despesas justificáveis — aquisição de bens e serviços | B15: D_BENS | C15: =Inputs!$C$20+Inputs!$C$21+Inputs!$C$22+Inputs!$C$24+Inputs!$C$25+Inputs!$C$44 | D15: =Inputs!$D$20+Inputs!$D$21+Inputs!$D$22+Inputs!$D$24+Inputs!$D$25+Inputs!$D$44 | E15: =Inputs!$E$20+Inputs!$E$21+Inputs!$E$22+Inputs!$E$24+Inputs!$E$25+Inputs!$E$44 | F15: Art. 31.º n.º 13 al. e) CIRS. Inclui os honorários, quando o modelo de colaboração for o de prestação de serviços.
A16: Despesas justificáveis — aquisições de investimento do ano | B16: D_INV | C16: =Inputs!$C$27+Inputs!$C$28+Inputs!$C$29+Inputs!$C$30 | D16: =Inputs!$D$27+Inputs!$D$28+Inputs!$D$29+Inputs!$D$30 | E16: =Inputs!$E$27+Inputs!$E$28+Inputs!$E$29+Inputs!$E$30 | F16: A CONFIRMAR pela Fiscalidade: elegibilidade e grau de afetação das aquisições de investimento para efeitos do art. 31.º n.º 13 al. e). Efeito de ano 1 apenas. Ver R1-08.
A17: Total de despesas justificadas | B17: D_TOT | C17: =SUM($C$13:$C$16) | D17: =SUM($D$13:$D$16) | E17: =SUM($E$13:$E$16)
A18: Acréscimo por insuficiência de justificação | B18: ACRESC | C18: =MAX(0,$C$12-$C$17) | D18: =MAX(0,$D$12-$D$17) | E18: =MAX(0,$E$12-$E$17) | F18: Art. 31.º n.º 13 CIRS: acresce ao rendimento tributável a diferença positiva.
A19: Rendimento da categoria B antes da dedução de contribuições | B19: RB_CATB | C19: =$C$11+$C$18 | D19: =$D$11+$D$18 | E19: =$E$11+$E$18
A20: Segurança Social — trabalhador independente
A21: Rendimento relevante | B21: SS_REL | C21: =$C$8*Parametros!$C$7 | D21: =$D$8*Parametros!$C$7 | E21: =$E$8*Parametros!$C$7 | F21: Art. 162.º Cód. Contributivo: 70% do valor das prestações de serviços. A inclusão da receita de cedência de espaço depende de esta ser qualificada como prestação de serviços — N1-04.
A22: Base de incidência anual, limitada ao teto | B22: SS_BASE | C22: =MIN($C$21,Parametros!$C$6*Parametros!$C$9*12) | D22: =MIN($D$21,Parametros!$C$6*Parametros!$C$9*12) | E22: =MIN($E$21,Parametros!$C$6*Parametros!$C$9*12) | F22: Teto mensal de 12 x IAS.
A23: Contribuição anual para a Segurança Social | B23: SS_CONTR | C23: =MAX($C$22*Parametros!$C$8,Parametros!$C$10*12) | D23: =MAX($D$22*Parametros!$C$8,Parametros!$C$10*12) | E23: =MAX($E$22*Parametros!$C$8,Parametros!$C$10*12) | F23: Bloco ausente da ata. Na via 1 a base é a faturação bruta, não a margem — é aqui que está o maior diferencial entre as vias.
A24: Parte dedutível em IRS | B24: SS_DED | C24: =MAX(0,$C$23-$C$8*Parametros!$C$27) | D24: =MAX(0,$D$23-$D$8*Parametros!$C$27) | E24: =MAX(0,$E$23-$E$8*Parametros!$C$27) | F24: Art. 31.º n.º 2 CIRS: dedutível apenas na parte que excede 10% do rendimento bruto.
A25: Rendimento líquido da categoria B | B25: RL_CATB | C25: =$C$19-$C$24 | D25: =$D$19-$D$24 | E25: =$E$19-$E$24
A26: IRS do agregado
A27: Rendimento da sócia sujeito a englobamento | B27: R_JUL | C27: =$C$25 | D27: =$D$25 | E27: =$E$25 | F27: Só categoria B. Não há remuneração de gerência nesta via.
A28: Rendimento do cônjuge fora da estrutura | B28: R_CONJ | C28: =Inputs!$C$37 | D28: =Inputs!$D$37 | E28: =Inputs!$E$37
A29: Rendimento coletável do agregado — com a atividade | B29: RC_COM | C29: =$C$27+$C$28 | D29: =$D$27+$D$28 | E29: =$E$27+$E$28
A30: Rendimento coletável do agregado — sem a atividade | B30: RC_SEM | C30: =$C$28 | D30: =$D$28 | E30: =$E$28 | F30: Contrafactual. O diferencial entre as duas coletas é o IRS realmente imputável à atividade e é o que torna as quatro vias comparáveis.
A31: Fator do quociente conjugal | B31: FATOR | C31: =IF(Inputs!$C$38=1,2,1) | D31: =IF(Inputs!$D$38=1,2,1) | E31: =IF(Inputs!$E$38=1,2,1) | F31: Art. 69.º CIRS. Isolado numa linha para que as fórmulas de coleta caibam num ecrã.
A32: Rendimento coletável ajustado ao quociente — com a atividade | B32: RCQ_COM | C32: =$C$29/$C$31 | D32: =$D$29/$D$31 | E32: =$E$29/$E$31
A33: Rendimento coletável ajustado ao quociente — sem a atividade | B33: RCQ_SEM | C33: =$C$30/$C$31 | D33: =$D$30/$D$31 | E33: =$E$30/$E$31
A34: Coleta com a atividade (incl. taxa adicional de solidariedade) | B34: COL_COM | C34: =$C$31*(SUMPRODUCT(($C$32>Parametros!$B$55:$B$63)*($C$32-Parametros!$B$55:$B$63)*Parametros!$E$55:$E$63)+SUMPRODUCT(($C$32>Parametros!$B$67:$B$68)*($C$32-Parametros!$B$67:$B$68)*Parametros!$E$67:$E$68)) | D34: =$D$31*(SUMPRODUCT(($D$32>Parametros!$B$55:$B$63)*($D$32-Parametros!$B$55:$B$63)*Parametros!$E$55:$E$63)+SUMPRODUCT(($D$32>Parametros!$B$67:$B$68)*($D$32-Parametros!$B$67:$B$68)*Parametros!$E$67:$E$68)) | E34: =$E$31*(SUMPRODUCT(($E$32>Parametros!$B$55:$B$63)*($E$32-Parametros!$B$55:$B$63)*Parametros!$E$55:$E$63)+SUMPRODUCT(($E$32>Parametros!$B$67:$B$68)*($E$32-Parametros!$B$67:$B$68)*Parametros!$E$67:$E$68)) | F34: Escalões na folha Parâmetros. Art. 68.º, 68.º-A e 69.º CIRS.
A35: Coleta sem a atividade | B35: COL_SEM | C35: =$C$31*(SUMPRODUCT(($C$33>Parametros!$B$55:$B$63)*($C$33-Parametros!$B$55:$B$63)*Parametros!$E$55:$E$63)+SUMPRODUCT(($C$33>Parametros!$B$67:$B$68)*($C$33-Parametros!$B$67:$B$68)*Parametros!$E$67:$E$68)) | D35: =$D$31*(SUMPRODUCT(($D$33>Parametros!$B$55:$B$63)*($D$33-Parametros!$B$55:$B$63)*Parametros!$E$55:$E$63)+SUMPRODUCT(($D$33>Parametros!$B$67:$B$68)*($D$33-Parametros!$B$67:$B$68)*Parametros!$E$67:$E$68)) | E35: =$E$31*(SUMPRODUCT(($E$33>Parametros!$B$55:$B$63)*($E$33-Parametros!$B$55:$B$63)*Parametros!$E$55:$E$63)+SUMPRODUCT(($E$33>Parametros!$B$67:$B$68)*($E$33-Parametros!$B$67:$B$68)*Parametros!$E$67:$E$68))
A36: IRS imputável à atividade | B36: IRS_ATIV | C36: =$C$34-$C$35 | D36: =$D$34-$D$35 | E36: =$E$34-$E$35
A37: IRS total do agregado, após deduções à coleta (memória) | B37: IRS_TOT | C37: =MAX(0,$C$34-Inputs!$C$40) | D37: =MAX(0,$D$34-Inputs!$D$40) | E37: =MAX(0,$E$34-Inputs!$E$40) | F37: Não entra na comparação entre vias; serve para o enquadramento do capítulo 3.
A38: Resultado
A39: Caixa gerada pela atividade, antes de impostos e contribuições | B39: CAIXA | C39: =Inputs!$C$42+Inputs!$C$43+Inputs!$C$17-(Inputs!$C$19+Inputs!$C$20+Inputs!$C$21+Inputs!$C$22+Inputs!$C$24+Inputs!$C$25+Inputs!$C$44) | D39: =Inputs!$D$42+Inputs!$D$43+Inputs!$D$17-(Inputs!$D$19+Inputs!$D$20+Inputs!$D$21+Inputs!$D$22+Inputs!$D$24+Inputs!$D$25+Inputs!$D$44) | E39: =Inputs!$E$42+Inputs!$E$43+Inputs!$E$17-(Inputs!$E$19+Inputs!$E$20+Inputs!$E$21+Inputs!$E$22+Inputs!$E$24+Inputs!$E$25+Inputs!$E$44) | F39: Caixa gerada pela atividade, igual nas quatro vias por construção. Exclui o investimento inicial, que é um efeito de ano 1 e está isolado na folha IVA e na linha própria abaixo.
A40: Total de impostos e contribuições | B40: CARGA | C40: =$C$36+$C$23 | D40: =$D$36+$D$23 | E40: =$E$36+$E$23 | F40: IRS imputável à atividade + contribuições para a Segurança Social.
A41: Taxa de esforço efetiva sobre a caixa gerada | B41: TAXA_EF | C41: =IF($C$39<=0,0,$C$40/$C$39) | D41: =IF($D$39<=0,0,$D$40/$D$39) | E41: =IF($E$39<=0,0,$E$40/$E$39)
...

Sheet V2_ENI_ContOrg
A1: Via 2 — ENI com opção por contabilidade organizada
A2: Mantém o ENI e passa a deduzir os custos efetivos. Duas consequências que a ata não quantificou: a base de incidência da Segurança Social deixa de ser 70% da faturação e passa a ser o lucro tributável, e a opção vincula por 3 anos.
A4: Rubrica | B4: Ref. | C4: Baixo | D4: Base | E4: Alto | F4: Nota / norma
A5: Apuramento do lucro tributável
A6: Receita bruta (fisioterapia + cedência de espaço) | B6: FAT | C6: =Inputs!$C$42+Inputs!$C$43 | D6: =Inputs!$D$42+Inputs!$D$43 | E6: =Inputs!$E$42+Inputs!$E$43
A7: Custos operacionais dedutíveis (excl. honorários) | B7: C_OP | C7: =Inputs!$C$19+Inputs!$C$20+Inputs!$C$21+Inputs!$C$22+Inputs!$C$24+Inputs!$C$25 | D7: =Inputs!$D$19+Inputs!$D$20+Inputs!$D$21+Inputs!$D$22+Inputs!$D$24+Inputs!$D$25 | E7: =Inputs!$E$19+Inputs!$E$20+Inputs!$E$21+Inputs!$E$22+Inputs!$E$24+Inputs!$E$25
A8: Custo com os colaboradores | B8: C_HON | C8: =Inputs!$C$44 | D8: =Inputs!$D$44 | E8: =Inputs!$E$44 | F8: Dedutíveis como custo da atividade (ata, ponto 4). Sujeitos ao risco de requalificação tratado na fase 2 do P1.
A9: Amortizações do exercício | B9: AMORT | C9: =Inputs!$C$27*Parametros!$C$44+(Inputs!$C$28+Inputs!$C$29)*Parametros!$C$45+Inputs!$C$30*Parametros!$C$46 | D9: =Inputs!$D$27*Parametros!$C$44+(Inputs!$D$28+Inputs!$D$29)*Parametros!$C$45+Inputs!$D$30*Parametros!$C$46 | E9: =Inputs!$E$27*Parametros!$C$44+(Inputs!$E$28+Inputs!$E$29)*Parametros!$C$45+Inputs!$E$30*Parametros!$C$46 | F9: Taxas na folha Parâmetros. Obras em imóvel alheio: confirmar se o período do contrato de arrendamento é inferior ao decorrente da taxa.
A10: Lucro tributável antes de contribuições | B10: LT_ANTES | C10: =$C$6-$C$7-$C$8-$C$9 | D10: =$D$6-$D$7-$D$8-$D$9 | E10: =$E$6-$E$7-$E$8-$E$9
A11: Segurança Social — trabalhador independente com contabilidade organizada
A12: Base de incidência anual, limitada ao teto | B12: SS_BASE | C12: =MIN(MAX($C$10,0),Parametros!$C$6*Parametros!$C$9*12) | D12: =MIN(MAX($D$10,0),Parametros!$C$6*Parametros!$C$9*12) | E12: =MIN(MAX($E$10,0),Parametros!$C$6*Parametros!$C$9*12) | F12: Art. 162.º n.º 3 Cód. Contributivo: com contabilidade organizada o rendimento relevante é o lucro tributável, não 70% da faturação. CONFIRMAR (R1-12). Modelado em regime de cruzeiro: no primeiro ano a base é a declarada no início de atividade.
A13: Contribuição anual para a Segurança Social | B13: SS_CONTR | C13: =MAX($C$12*Parametros!$C$8,Parametros!$C$10*12) | D13: =MAX($D$12*Parametros!$C$8,Parametros!$C$10*12) | E13: =MAX($E$12*Parametros!$C$8,Parametros!$C$10*12)
A14: Lucro tributável após dedução das contribuições | B14: LT | C14: =MAX(0,$C$10-$C$13) | D14: =MAX(0,$D$10-$D$13) | E14: =MAX(0,$E$10-$E$13) | F14: Contribuições obrigatórias dedutíveis na totalidade nesta via, ao contrário do art. 31.º n.º 2.
A15: IRS do agregado
A16: Rendimento da sócia sujeito a englobamento | B16: R_JUL | C16: =$C$14 | D16: =$D$14 | E16: =$E$14 | F16: Lucro tributável real. Não há dedução específica de 4.104 € nesta via.
A17: Rendimento do cônjuge fora da estrutura | B17: R_CONJ | C17: =Inputs!$C$37 | D17: =Inputs!$D$37 | E17: =Inputs!$E$37
A18: Rendimento coletável do agregado — com a atividade | B18: RC_COM | C18: =$C$16+$C$17 | D18: =$D$16+$D$17 | E18: =$E$16+$E$17
A19: Rendimento coletável do agregado — sem a atividade | B19: RC_SEM | C19: =$C$17 | D19: =$D$17 | E19: =$E$17 | F19: Contrafactual. O diferencial entre as duas coletas é o IRS realmente imputável à atividade e é o que torna as quatro vias comparáveis.
A20: Fator do quociente conjugal | B20: FATOR | C20: =IF(Inputs!$C$38=1,2,1) | D20: =IF(Inputs!$D$38=1,2,1) | E20: =IF(Inputs!$E$38=1,2,1) | F20: Art. 69.º CIRS. Isolado numa linha para que as fórmulas de coleta caibam num ecrã.
A21: Rendimento coletável ajustado ao quociente — com a atividade | B21: RCQ_COM | C21: =$C$18/$C$20 | D21: =$D$18/$D$20 | E21: =$E$18/$E$20
A22: Rendimento coletável ajustado ao quociente — sem a atividade | B22: RCQ_SEM | C22: =$C$19/$C$20 | D22: =$D$19/$D$20 | E22: =$E$19/$E$20
A23: Coleta com a atividade (incl. taxa adicional de solidariedade) | B23: COL_COM | C23: =$C$20*(SUMPRODUCT(($C$21>Parametros!$B$55:$B$63)*($C$21-Parametros!$B$55:$B$63)*Parametros!$E$55:$E$63)+SUMPRODUCT(($C$21>Parametros!$B$67:$B$68)*($C$21-Parametros!$B$67:$B$68)*Parametros!$E$67:$E$68)) | D23: =$D$20*(SUMPRODUCT(($D$21>Parametros!$B$55:$B$63)*($D$21-Parametros!$B$55:$B$63)*Parametros!$E$55:$E$63)+SUMPRODUCT(($D$21>Parametros!$B$67:$B$68)*($D$21-Parametros!$B$67:$B$68)*Parametros!$E$67:$E$68)) | E23: =$E$20*(SUMPRODUCT(($E$21>Parametros!$B$55:$B$63)*($E$21-Parametros!$B$55:$B$63)*Parametros!$E$55:$E$63)+SUMPRODUCT(($E$21>Parametros!$B$67:$B$68)*($E$21-Parametros!$B$67:$B$68)*Parametros!$E$67:$E$68)) | F23: Escalões na folha Parâmetros. Art. 68.º, 68.º-A e 69.º CIRS.
A24: Coleta sem a atividade | B24: COL_SEM | C24: =$C$20*(SUMPRODUCT(($C$22>Parametros!$B$55:$B$63)*($C$22-Parametros!$B$55:$B$63)*Parametros!$E$55:$E$63)+SUMPRODUCT(($C$22>Parametros!$B$67:$B$68)*($C$22-Parametros!$B$67:$B$68)*Parametros!$E$67:$E$68)) | D24: =$D$20*(SUMPRODUCT(($D$22>Parametros!$B$55:$B$63)*($D$22-Parametros!$B$55:$B$63)*Parametros!$E$55:$E$63)+SUMPRODUCT(($D$22>Parametros!$B$67:$B$68)*($D$22-Parametros!$B$67:$B$68)*Parametros!$E$67:$E$68)) | E24: =$E$20*(SUMPRODUCT(($E$22>Parametros!$B$55:$B$63)*($E$22-Parametros!$B$55:$B$63)*Parametros!$E$55:$E$63)+SUMPRODUCT(($E$22>Parametros!$B$67:$B$68)*($E$22-Parametros!$B$67:$B$68)*Parametros!$E$67:$E$68))
A25: IRS imputável à atividade | B25: IRS_ATIV | C25: =$C$23-$C$24 | D25: =$D$23-$D$24 | E25: =$E$23-$E$24
A26: IRS total do agregado, após deduções à coleta (memória) | B26: IRS_TOT | C26: =MAX(0,$C$23-Inputs!$C$40) | D26: =MAX(0,$D$23-Inputs!$D$40) | E26: =MAX(0,$E$23-Inputs!$E$40) | F26: Não entra na comparação entre vias; serve para o enquadramento do capítulo 3.
A27: Resultado
A28: Caixa gerada pela atividade, antes de impostos e contribuições | B28: CAIXA | C28: =Inputs!$C$42+Inputs!$C$43+Inputs!$C$17-(Inputs!$C$19+Inputs!$C$20+Inputs!$C$21+Inputs!$C$22+Inputs!$C$24+Inputs!$C$25+Inputs!$C$44) | D28: =Inputs!$D$42+Inputs!$D$43+Inputs!$D$17-(Inputs!$D$19+Inputs!$D$20+Inputs!$D$21+Inputs!$D$22+Inputs!$D$24+Inputs!$D$25+Inputs!$D$44) | E28: =Inputs!$E$42+Inputs!$E$43+Inputs!$E$17-(Inputs!$E$19+Inputs!$E$20+Inputs!$E$21+Inputs!$E$22+Inputs!$E$24+Inputs!$E$25+Inputs!$E$44) | F28: Caixa gerada pela atividade, igual nas quatro vias por construção. Exclui o investimento inicial, que é um efeito de ano 1 e está isolado na folha IVA e na linha própria abaixo.
A29: Total de impostos e contribuições | B29: CARGA | C29: =$C$25+$C$13 | D29: =$D$25+$D$13 | E29: =$E$25+$E$13 | F29: IRS imputável à atividade + contribuições para a Segurança Social.
A30: Taxa de esforço efetiva sobre a caixa gerada | B30: TAXA_EF | C30: =IF($C$28<=0,0,$C$29/$C$28) | D30: =IF($D$28<=0,0,$D$29/$D$28) | E30: =IF($E$28<=0,0,$E$29/$E$28)
A31: Valor retido na sociedade (não disponibilizado à sócia) | B31: RETIDO | C31: =0 | D31: =0 | E31: =0
A32: Valor atribuído ao cônjuge por via de dividendos, líquido | B32: LIQ_CJ | C32: =0 | D32: =0 | E32: =0 | F32: Só via 4. É uma transferência real de rendimento dentro do agregado e tem de ser explicitada — não é indiferente à sócia.
A33: LÍQUIDO DISPONÍVEL PARA A SÓCIA | B33: LIQ_SOC | C33: =$C$28-$C$29-$C$31-$C$32 | D33: =$D$28-$D$29-$D$31-$D$32 | E33: =$E$28-$E$29-$E$31-$E$32
A34: LÍQUIDO DISPONÍVEL PARA O AGREGADO | B34: LIQ_AGR | C34: =$C$33+$C$32 | D34: =$D$33+$D$32 | E34: =$E$33+$E$32
A35: Memória — investimento e IVA não dedutível suportados no ano 1 | B35: INV_A1 | C35: =Inputs!$C$27+Inputs!$C$28+Inputs!$C$29+Inputs!$C$30 | D35: =Inputs!$D$27+Inputs!$D$28+Inputs!$D$29+Inputs!$D$30 | E35: =Inputs!$E$27+Inputs!$E$28+Inputs!$E$29+Inputs!$E$30 | F35: Excluído da comparação anual acima. Quantificação do IVA na folha IVA.

Sheet V3_Soc_Transparente
A1: Via 3 — Sociedade sujeita a transparência fiscal (art. 6.º CIRC)
A2: Sociedade detida a 100% pela Dra. Júlia. O lucro é imputado à sócia e tributado em IRS independentemente de distribuição (art. 6.º n.º 3 CIRC e art. 20.º CIRS). A sociedade não é tributada em IRC sobre o lucro, mas mantém-se sujeita a tributações autónomas (art. 12.º CIRC).
A4: Rubrica | B4: Ref. | C4: Baixo | D4: Base | E4: Alto | F4: Nota / norma
A5: Apuramento ao nível da sociedade
A6: Receita bruta (fisioterapia + cedência de espaço) | B6: FAT | C6: =Inputs!$C$42+Inputs!$C$43 | D6: =Inputs!$D$42+Inputs!$D$43 | E6: =Inputs!$E$42+Inputs!$E$43
A7: Custos operacionais (excl. honorários) | B7: C_OP | C7: =Inputs!$C$19+Inputs!$C$20+Inputs!$C$21+Inputs!$C$22+Inputs!$C$24+Inputs!$C$25 | D7: =Inputs!$D$19+Inputs!$D$20+Inputs!$D$21+Inputs!$D$22+Inputs!$D$24+Inputs!$D$25 | E7: =Inputs!$E$19+Inputs!$E$20+Inputs!$E$21+Inputs!$E$22+Inputs!$E$24+Inputs!$E$25
A8: Custo com os colaboradores | B8: C_HON | C8: =Inputs!$C$44 | D8: =Inputs!$D$44 | E8: =Inputs!$E$44
A9: Amortizações do exercício | B9: AMORT | C9: =Inputs!$C$27*Parametros!$C$44+(Inputs!$C$28+Inputs!$C$29)*Parametros!$C$45+Inputs!$C$30*Parametros!$C$46 | D9: =Inputs!$D$27*Parametros!$C$44+(Inputs!$D$28+Inputs!$D$29)*Parametros!$C$45+Inputs!$D$30*Parametros!$C$46 | E9: =Inputs!$E$27*Parametros!$C$44+(Inputs!$E$28+Inputs!$E$29)*Parametros!$C$45+Inputs!$E$30*Parametros!$C$46
A10: Remuneração bruta de gerência | B10: REM | C10: =Inputs!$C$32 | D10: =Inputs!$D$32 | E10: =Inputs!$E$32 | F10: Variável de decisão. É a única base de incidência contributiva nesta via.
A11: Base de incidência contributiva do MOE | B11: BASE_MOE | C11: =MAX($C$10,Parametros!$C$6*Parametros!$C$13*12) | D11: =MAX($D$10,Parametros!$C$6*Parametros!$C$13*12) | E11: =MAX($E$10,Parametros!$C$6*Parametros!$C$13*12) | F11: Base mínima de 1 x IAS por mês, mesmo com remuneração inferior ou nula.
A12: Contribuições a cargo da sociedade | B12: TSU_ENT | C12: =$C$11*Parametros!$C$11 | D12: =$D$11*Parametros!$C$11 | E12: =$E$11*Parametros!$C$11
A13: Lucro tributável | B13: LT | C13: =$C$6-$C$7-$C$8-$C$9-$C$10-$C$12 | D13: =$D$6-$D$7-$D$8-$D$9-$D$10-$D$12 | E13: =$E$6-$E$7-$E$8-$E$9-$E$10-$E$12
A14: Tributações autónomas | B14: TA | C14: =Inputs!$C$33 | D14: =Inputs!$D$33 | E14: =Inputs!$E$33 | F14: Devidas apesar da transparência fiscal — art. 12.º CIRC ressalva as tributações autónomas.
A15: Derrama municipal | B15: DERR | C15: =MAX($C$13,0)*Parametros!$C$36*Parametros!$C$37 | D15: =MAX($D$13,0)*Parametros!$C$36*Parametros!$C$37 | E15: =MAX($E$13,0)*Parametros!$C$36*Parametros!$C$37 | F15: Interruptor na folha Parâmetros, por defeito a 0. A incidência de derrama sobre sociedade transparente é questão controvertida — ver R1-13. Não afirmar no relatório sem decisão da Fiscalidade.
A16: Lucro imputável à sócia | B16: LUCRO_IMP | C16: =MAX($C$13,0) | D16: =MAX($D$13,0) | E16: =MAX($E$13,0) | F16: Imputado independentemente de distribuição. Prejuízo fiscal não é imputado — é reportado na esfera da sociedade.
A17: Esfera da sócia
A18: Contribuições a cargo da sócia (categoria A) | B18: SS_TRAB | C18: =$C$11*Parametros!$C$12 | D18: =$D$11*Parametros!$C$12 | E18: =$E$11*Parametros!$C$12
A19: Dedução específica da categoria A | B19: DED_A | C19: =MIN($C$10,MAX(Parametros!$C$30,$C$18)) | D19: =MIN($D$10,MAX(Parametros!$C$30,$D$18)) | E19: =MIN($E$10,MAX(Parametros!$C$30,$E$18)) | F19: Art. 25.º n.º 1 al. a) e n.º 2 CIRS: o maior entre 4.104 € e as contribuições, com o limite do próprio rendimento.
A20: Rendimento líquido da categoria A | B20: RL_CATA | C20: =MAX(0,$C$10-$C$19) | D20: =MAX(0,$D$10-$D$19) | E20: =MAX(0,$E$10-$E$19)
A21: IRS do agregado
A22: Rendimento da sócia sujeito a englobamento | B22: R_JUL | C22: =$C$20+$C$16 | D22: =$D$20+$D$16 | E22: =$E$20+$E$16 | F22: Categoria A (remuneração de gerência) + categoria B (lucro imputado, art. 20.º CIRS).
A23: Rendimento do cônjuge fora da estrutura | B23: R_CONJ | C23: =Inputs!$C$37 | D23: =Inputs!$D$37 | E23: =Inputs!$E$37
A24: Rendimento coletável do agregado — com a atividade | B24: RC_COM | C24: =$C$22+$C$23 | D24: =$D$22+$D$23 | E24: =$E$22+$E$23
A25: Rendimento coletável do agregado — sem a atividade | B25: RC_SEM | C25: =$C$23 | D25: =$D$23 | E25: =$E$23 | F25: Contrafactual. O diferencial entre as duas coletas é o IRS realmente imputável à atividade e é o que torna as quatro vias comparáveis.
A26: Fator do quociente conjugal | B26: FATOR | C26: =IF(Inputs!$C$38=1,2,1) | D26: =IF(Inputs!$D$38=1,2,1) | E26: =IF(Inputs!$E$38=1,2,1) | F26: Art. 69.º CIRS. Isolado numa linha para que as fórmulas de coleta caibam num ecrã.
A27: Rendimento coletável ajustado ao quociente — com a atividade | B27: RCQ_COM | C27: =$C$24/$C$26 | D27: =$D$24/$D$26 | E27: =$E$24/$E$26
A28: Rendimento coletável ajustado ao quociente — sem a atividade | B28: RCQ_SEM | C28: =$C$25/$C$26 | D28: =$D$25/$D$26 | E28: =$E$25/$E$26
A29: Coleta com a atividade (incl. taxa adicional de solidariedade) | B29: COL_COM | C29: =$C$26*(SUMPRODUCT(($C$27>Parametros!$B$55:$B$63)*($C$27-Parametros!$B$55:$B$63)*Parametros!$E$55:$E$63)+SUMPRODUCT(($C$27>Parametros!$B$67:$B$68)*($C$27-Parametros!$B$67:$B$68)*Parametros!$E$67:$E$68)) | D29: =$D$26*(SUMPRODUCT(($D$27>Parametros!$B$55:$B$63)*($D$27-Parametros!$B$55:$B$63)*Parametros!$E$55:$E$63)+SUMPRODUCT(($D$27>Parametros!$B$67:$B$68)*($D$27-Parametros!$B$67:$B$68)*Parametros!$E$67:$E$68)) | E29: =$E$26*(SUMPRODUCT(($E$27>Parametros!$B$55:$B$63)*($E$27-Parametros!$B$55:$B$63)*Parametros!$E$55:$E$63)+SUMPRODUCT(($E$27>Parametros!$B$67:$B$68)*($E$27-Parametros!$B$67:$B$68)*Parametros!$E$67:$E$68)) | F29: Escalões na folha Parâmetros. Art. 68.º, 68.º-A e 69.º CIRS.
A30: Coleta sem a atividade | B30: COL_SEM | C30: =$C$26*(SUMPRODUCT(($C$28>Parametros!$B$55:$B$63)*($C$28-Parametros!$B$55:$B$63)*Parametros!$E$55:$E$63)+SUMPRODUCT(($C$28>Parametros!$B$67:$B$68)*($C$28-Parametros!$B$67:$B$68)*Parametros!$E$67:$E$68)) | D30: =$D$26*(SUMPRODUCT(($D$28>Parametros!$B$55:$B$63)*($D$28-Parametros!$B$55:$B$63)*Parametros!$E$55:$E$63)+SUMPRODUCT(($D$28>Parametros!$B$67:$B$68)*($D$28-Parametros!$B$67:$B$68)*Parametros!$E$67:$E$68)) | E30: =$E$26*(SUMPRODUCT(($E$28>Parametros!$B$55:$B$63)*($E$28-Parametros!$B$55:$B$63)*Parametros!$E$55:$E$63)+SUMPRODUCT(($E$28>Parametros!$B$67:$B$68)*($E$28-Parametros!$B$67:$B$68)*Parametros!$E$67:$E$68))
A31: IRS imputável à atividade | B31: IRS_ATIV | C31: =$C$29-$C$30 | D31: =$D$29-$D$30 | E31: =$E$29-$E$30
A32: IRS total do agregado, após deduções à coleta (memória) | B32: IRS_TOT | C32: =MAX(0,$C$29-Inputs!$C$40) | D32: =MAX(0,$D$29-Inputs!$D$40) | E32: =MAX(0,$E$29-Inputs!$E$40) | F32: Não entra na comparação entre vias; serve para o enquadramento do capítulo 3.
A33: Resultado
A34: Caixa gerada pela atividade, antes de impostos e contribuições | B34: CAIXA | C34: =Inputs!$C$42+Inputs!$C$43+Inputs!$C$17-(Inputs!$C$19+Inputs!$C$20+Inputs!$C$21+Inputs!$C$22+Inputs!$C$24+Inputs!$C$25+Inputs!$C$44) | D34: =Inputs!$D$42+Inputs!$D$43+Inputs!$D$17-(Inputs!$D$19+Inputs!$D$20+Inputs!$D$21+Inputs!$D$22+Inputs!$D$24+Inputs!$D$25+Inputs!$D$44) | E34: =Inputs!$E$42+Inputs!$E$43+Inputs!$E$17-(Inputs!$E$19+Inputs!$E$20+Inputs!$E$21+Inputs!$E$22+Inputs!$E$24+Inputs!$E$25+Inputs!$E$44) | F34: Caixa gerada pela atividade, igual nas quatro vias por construção. Exclui o investimento inicial, que é um efeito de ano 1 e está isolado na folha IVA e na linha própria abaixo.
A35: Total de impostos e contribuições | B35: CARGA | C35: =$C$31+$C$18+$C$12+$C$14+$C$15 | D35: =$D$31+$D$18+$D$12+$D$14+$D$15 | E35: =$E$31+$E$18+$E$12+$E$14+$E$15 | F35: IRS imputável + contribuições da sócia + contribuições da sociedade + tributações autónomas + derrama. A distribuição do lucro já imputado não é novamente tributada.
A36: Taxa de esforço efetiva sobre a caixa gerada | B36: TAXA_EF | C36: =IF($C$34<=0,0,$C$35/$C$34) | D36: =IF($D$34<=0,0,$D$35/$D$34) | E36: =IF($E$34<=0,0,$E$35/$E$34)
A37: Valor retido na sociedade (não disponibilizado à sócia) | B37: RETIDO | C37: =MAX(0,(Inputs!$C$42+Inputs!$C$43+Inputs!$C$17-(Inputs!$C$19+Inputs!$C$20+Inputs!$C$21+Inputs!$C$22+Inputs!$C$24+Inputs!$C$25+Inputs!$C$44))-$C$10-$C$12-$C$14-$C$15)*(1-Inputs!$C$34) | D37: =MAX(0,(Inputs!$D$42+Inputs!$D$43+Inputs!$D$17-(Inputs!$D$19+Inputs!$D$20+Inputs!$D$21+Inputs!$D$22+Inputs!$D$24+Inputs!$D$25+Inputs!$D$44))-$D$10-$D$12-$D$14-$D$15)*(1-Inputs!$D$34) | E37: =MAX(0,(Inputs!$E$42+Inputs!$E$43+Inputs!$E$17-(Inputs!$E$19+Inputs!$E$20+Inputs!$E$21+Inputs!$E$22+Inputs!$E$24+Inputs!$E$25+Inputs!$E$44))-$E$10-$E$12-$E$14-$E$15)*(1-Inputs!$E$34)
A38: Valor atribuído ao cônjuge por via de dividendos, líquido | B38: LIQ_CJ | C38: =0 | D38: =0 | E38: =0 | F38: Só via 4. É uma transferência real de rendimento dentro do agregado e tem de ser explicitada — não é indiferente à sócia.
A39: LÍQUIDO DISPONÍVEL PARA A SÓCIA | B39: LIQ_SOC | C39: =$C$34-$C$35-$C$37-$C$38 | D39: =$D$34-$D$35-$D$37-$D$38 | E39: =$E$34-$E$35-$E$37-$E$38
A40: LÍQUIDO DISPONÍVEL PARA O AGREGADO | B40: LIQ_AGR | C40: =$C$39+$C$38 | D40: =$D$39+$D$38 | E40: =$E$39+$E$38
A41: Memória — investimento e IVA não dedutível suportados no ano 1 | B41: INV_A1 | C41: =Inputs!$C$27+Inputs!$C$28+Inputs!$C$29+Inputs!$C$30 | D41: =Inputs!$D$27+Inputs!$D$28+Inputs!$D$29+Inputs!$D$30 | E41: =Inputs!$E$27+Inputs!$E$28+Inputs!$E$29+Inputs!$E$30 | F41: Excluído da comparação anual acima. Quantificação do IVA na folha IVA.

Sheet V4_Soc_NaoTransparente
A1: Via 4 — Sociedade fora da transparência fiscal (entrada do cônjuge)
A2: Pressupõe que a entrada do cônjuge afasta o regime do art. 6.º CIRC (ver N1 para o teste). O lucro passa a ser tributado em IRC e a distribuição é tributada de novo na esfera dos sócios. A pergunta a que esta folha responde não é 'sai da transparência?' mas 'compensa sair?'.
A4: Rubrica | B4: Ref. | C4: Baixo | D4: Base | E4: Alto | F4: Nota / norma
A5: Apuramento ao nível da sociedade
A6: Receita isenta (fisioterapia + cedência de espaço, se isenta) | B6: FAT | C6: =Inputs!$C$42+IF(Inputs!$C$16=1,0,Inputs!$C$43) | D6: =Inputs!$D$42+IF(Inputs!$D$16=1,0,Inputs!$D$43) | E6: =Inputs!$E$42+IF(Inputs!$E$16=1,0,Inputs!$E$43)
A7: Receita sujeita a IVA (cônjuge e/ou cedência tributada) | B7: FAT_T | C7: =Inputs!$C$47 | D7: =Inputs!$D$47 | E7: =Inputs!$E$47
A8: Custos operacionais (excl. honorários) | B8: C_OP | C8: =Inputs!$C$19+Inputs!$C$20+Inputs!$C$21+Inputs!$C$22+Inputs!$C$24+Inputs!$C$25 | D8: =Inputs!$D$19+Inputs!$D$20+Inputs!$D$21+Inputs!$D$22+Inputs!$D$24+Inputs!$D$25 | E8: =Inputs!$E$19+Inputs!$E$20+Inputs!$E$21+Inputs!$E$22+Inputs!$E$24+Inputs!$E$25
A9: Custo com os colaboradores | B9: C_HON | C9: =Inputs!$C$44 | D9: =Inputs!$D$44 | E9: =Inputs!$E$44
A10: Amortizações do exercício | B10: AMORT | C10: =Inputs!$C$27*Parametros!$C$44+(Inputs!$C$28+Inputs!$C$29)*Parametros!$C$45+Inputs!$C$30*Parametros!$C$46 | D10: =Inputs!$D$27*Parametros!$C$44+(Inputs!$D$28+Inputs!$D$29)*Parametros!$C$45+Inputs!$D$30*Parametros!$C$46 | E10: =Inputs!$E$27*Parametros!$C$44+(Inputs!$E$28+Inputs!$E$29)*Parametros!$C$45+Inputs!$E$30*Parametros!$C$46
A11: Remuneração bruta de gerência | B11: REM | C11: =Inputs!$C$32 | D11: =Inputs!$D$32 | E11: =Inputs!$E$32
A12: Base de incidência contributiva do MOE | B12: BASE_MOE | C12: =MAX($C$11,Parametros!$C$6*Parametros!$C$13*12) | D12: =MAX($D$11,Parametros!$C$6*Parametros!$C$13*12) | E12: =MAX($E$11,Parametros!$C$6*Parametros!$C$13*12)
A13: Contribuições a cargo da sociedade | B13: TSU_ENT | C13: =$C$12*Parametros!$C$11 | D13: =$D$12*Parametros!$C$11 | E13: =$E$12*Parametros!$C$11
A14: Lucro tributável | B14: LT | C14: =$C$6+$C$7-$C$8-$C$9-$C$10-$C$11-$C$13 | D14: =$D$6+$D$7-$D$8-$D$9-$D$10-$D$11-$D$13 | E14: =$E$6+$E$7-$E$8-$E$9-$E$10-$E$11-$E$13
A15: IRC | B15: IRC | C15: =MIN(MAX($C$14,0),Parametros!$C$34)*Parametros!$C$33+MAX(0,MAX($C$14,0)-Parametros!$C$34)*Parametros!$C$35 | D15: =MIN(MAX($D$14,0),Parametros!$C$34)*Parametros!$C$33+MAX(0,MAX($D$14,0)-Parametros!$C$34)*Parametros!$C$35 | E15: =MIN(MAX($E$14,0),Parametros!$C$34)*Parametros!$C$33+MAX(0,MAX($E$14,0)-Parametros!$C$34)*Parametros!$C$35 | F15: Art. 87.º n.º 1 e 2 CIRC. Taxas de 2026 por confirmar — ver R1-11. O primeiro escalão só é aplicável se a sociedade qualificar como PME.
A16: Derrama municipal | B16: DERR | C16: =MAX($C$14,0)*Parametros!$C$36 | D16: =MAX($D$14,0)*Parametros!$C$36 | E16: =MAX($E$14,0)*Parametros!$C$36 | F16: Confirmar a taxa e eventual isenção do município para volume de negócios reduzido.
A17: Tributações autónomas | B17: TA | C17: =Inputs!$C$33 | D17: =Inputs!$D$33 | E17: =Inputs!$E$33
A18: Lucro após imposto | B18: LUCRO_LIQ | C18: =$C$14-$C$15-$C$16-$C$17 | D18: =$D$14-$D$15-$D$16-$D$17 | E18: =$E$14-$E$15-$E$16-$E$17
A19: Distribuição de resultados
A20: Caixa distribuível | B20: CX_DIST | C20: =MAX(0,(Inputs!$C$42+Inputs!$C$43+Inputs!$C$17-(Inputs!$C$19+Inputs!$C$20+Inputs!$C$21+Inputs!$C$22+Inputs!$C$24+Inputs!$C$25+Inputs!$C$44))-$C$11-$C$13-$C$15-$C$16-$C$17) | D20: =MAX(0,(Inputs!$D$42+Inputs!$D$43+Inputs!$D$17-(Inputs!$D$19+Inputs!$D$20+Inputs!$D$21+Inputs!$D$22+Inputs!$D$24+Inputs!$D$25+Inputs!$D$44))-$D$11-$D$13-$D$15-$D$16-$D$17) | E20: =MAX(0,(Inputs!$E$42+Inputs!$E$43+Inputs!$E$17-(Inputs!$E$19+Inputs!$E$20+Inputs!$E$21+Inputs!$E$22+Inputs!$E$24+Inputs!$E$25+Inputs!$E$44))-$E$11-$E$13-$E$15-$E$16-$E$17) | F20: Base de caixa: as amortizações não são saída de caixa, pelo que a caixa distribuível excede o lucro contabilístico enquanto o investimento estiver a ser amortizado.
A21: Política de distribuição | B21: POL | C21: =Inputs!$C$34 | D21: =Inputs!$D$34 | E21: =Inputs!$E$34 | F21: ALAVANCA PRINCIPAL desta via. A 0% de distribuição a via 4 domina; a 100% pode inverter-se.
A22: Montante distribuído | B22: DIST | C22: =$C$20*$C$21 | D22: =$D$20*$D$21 | E22: =$E$20*$E$21
A23: % do capital detida pelo cônjuge | B23: PCT_CJ | C23: =Inputs!$C$35 | D23: =Inputs!$D$35 | E23: =Inputs!$E$35
A24: Dividendo atribuído à sócia | B24: DIV_JUL | C24: =$C$22*(1-$C$23) | D24: =$D$22*(1-$D$23) | E24: =$E$22*(1-$E$23)
A25: Dividendo atribuído ao cônjuge | B25: DIV_CJ | C25: =$C$22*$C$23 | D25: =$D$22*$D$23 | E25: =$E$22*$E$23 | F25: Consequência não fiscal e frequentemente esquecida: a participação que afasta a transparência desloca essa fração do lucro para o cônjuge, em definitivo.
A26: Opção por englobamento dos dividendos (1 = sim / 0 = retenção liberatória) | B26: ENGLOB | C26: 0 | D26: 0 | E26: 0 | F26: ALAVANCA. Testar ambas. Art. 71.º n.º 6 e art. 40.º-A CIRS.
A27: Imposto sobre dividendos, por retenção liberatória | B27: IMP_DIV | C27: =IF($C$26=1,0,($C$24+$C$25)*Parametros!$C$38) | D27: =IF($D$26=1,0,($D$24+$D$25)*Parametros!$C$38) | E27: =IF($E$26=1,0,($E$24+$E$25)*Parametros!$C$38)
A28: IRS do agregado
A29: Rendimento da sócia sujeito a englobamento | B29: R_JUL | C29: =MAX(0,$C$11-MIN($C$11,MAX(Parametros!$C$30,$C$12*Parametros!$C$12)))+IF($C$26=1,$C$24*Parametros!$C$39,0) | D29: =MAX(0,$D$11-MIN($D$11,MAX(Parametros!$C$30,$D$12*Parametros!$C$12)))+IF($D$26=1,$D$24*Parametros!$C$39,0) | E29: =MAX(0,$E$11-MIN($E$11,MAX(Parametros!$C$30,$E$12*Parametros!$C$12)))+IF($E$26=1,$E$24*Parametros!$C$39,0) | F29: Categoria A líquida da dedução específica, mais 50% dos dividendos se houver englobamento (art. 40.º-A CIRS).
A30: Rendimento do cônjuge (incl. dividendos englobados, se aplicável) | B30: R_CONJ | C30: =Inputs!$C$37+IF($C$26=1,$C$25*Parametros!$C$39,0) | D30: =Inputs!$D$37+IF($D$26=1,$D$25*Parametros!$C$39,0) | E30: =Inputs!$E$37+IF($E$26=1,$E$25*Parametros!$C$39,0)
A31: Rendimento coletável do agregado — com a atividade | B31: RC_COM | C31: =$C$29+$C$30 | D31: =$D$29+$D$30 | E31: =$E$29+$E$30
A32: Rendimento coletável do agregado — sem a atividade | B32: RC_SEM | C32: =Inputs!$C$37 | D32: =Inputs!$D$37 | E32: =Inputs!$E$37 | F32: Contrafactual: apenas o rendimento do cônjuge fora da estrutura.
A33: Fator do quociente conjugal | B33: FATOR | C33: =IF(Inputs!$C$38=1,2,1) | D33: =IF(Inputs!$D$38=1,2,1) | E33: =IF(Inputs!$E$38=1,2,1)
A34: Rendimento coletável ajustado ao quociente — com a atividade | B34: RCQ_COM | C34: =$C$31/$C$33 | D34: =$D$31/$D$33 | E34: =$E$31/$E$33
A35: Rendimento coletável ajustado ao quociente — sem a atividade | B35: RCQ_SEM | C35: =$C$32/$C$33 | D35: =$D$32/$D$33 | E35: =$E$32/$E$33
A36: Coleta com a atividade (incl. taxa adicional de solidariedade) | B36: COL_COM | C36: =$C$33*(SUMPRODUCT(($C$34>Parametros!$B$55:$B$63)*($C$34-Parametros!$B$55:$B$63)*Parametros!$E$55:$E$63)+SUMPRODUCT(($C$34>Parametros!$B$67:$B$68)*($C$34-Parametros!$B$67:$B$68)*Parametros!$E$67:$E$68)) | D36: =$D$33*(SUMPRODUCT(($D$34>Parametros!$B$55:$B$63)*($D$34-Parametros!$B$55:$B$63)*Parametros!$E$55:$E$63)+SUMPRODUCT(($D$34>Parametros!$B$67:$B$68)*($D$34-Parametros!$B$67:$B$68)*Parametros!$E$67:$E$68)) | E36: =$E$33*(SUMPRODUCT(($E$34>Parametros!$B$55:$B$63)*($E$34-Parametros!$B$55:$B$63)*Parametros!$E$55:$E$63)+SUMPRODUCT(($E$34>Parametros!$B$67:$B$68)*($E$34-Parametros!$B$67:$B$68)*Parametros!$E$67:$E$68))
A37: Coleta sem a atividade | B37: COL_SEM | C37: =$C$33*(SUMPRODUCT(($C$35>Parametros!$B$55:$B$63)*($C$35-Parametros!$B$55:$B$63)*Parametros!$E$55:$E$63)+SUMPRODUCT(($C$35>Parametros!$B$67:$B$68)*($C$35-Parametros!$B$67:$B$68)*Parametros!$E$67:$E$68)) | D37: =$D$33*(SUMPRODUCT(($D$35>Parametros!$B$55:$B$63)*($D$35-Parametros!$B$55:$B$63)*Parametros!$E$55:$E$63)+SUMPRODUCT(($D$35>Parametros!$B$67:$B$68)*($D$35-Parametros!$B$67:$B$68)*Parametros!$E$67:$E$68)) | E37: =$E$33*(SUMPRODUCT(($E$35>Parametros!$B$55:$B$63)*($E$35-Parametros!$B$55:$B$63)*Parametros!$E$55:$E$63)+SUMPRODUCT(($E$35>Parametros!$B$67:$B$68)*($E$35-Parametros!$B$67:$B$68)*Parametros!$E$67:$E$68))
A38: IRS imputável à atividade | B38: IRS_ATIV | C38: =$C$36-$C$37 | D38: =$D$36-$D$37 | E38: =$E$36-$E$37
A39: IRS total do agregado, após deduções à coleta (memória) | B39: IRS_TOT | C39: =MAX(0,$C$36-Inputs!$C$40) | D39: =MAX(0,$D$36-Inputs!$D$40) | E39: =MAX(0,$E$36-Inputs!$E$40)
A40: Contribuições a cargo da sócia (memória) | B40: SS_TRAB | C40: =$C$12*Parametros!$C$12 | D40: =$D$12*Parametros!$C$12 | E40: =$E$12*Parametros!$C$12
A41: Resultado
...

Sheet IVA
A1: M1 — IVA sobre o investimento e custos correntes
A2: A fisioterapia é isenta pelo art. 9.º n.º 1 CIVA. É isenção incompleta: não confere direito à dedução. Todo o IVA suportado é custo. Esta folha quantifica o custo e testa as duas atenuantes: taxa reduzida em equipamento (Lista I) e sujeito passivo misto por entrada do cônjuge.
A4: Rubrica | B4: Ref. | C4: Baixo | D4: Base | E4: Alto | F4: Nota / norma
A5: IVA suportado no investimento inicial
A6: IVA nas obras | B6: I_OBRAS | C6: =Inputs!$C$27*Parametros!$C$41 | D6: =Inputs!$D$27*Parametros!$C$41 | E6: =Inputs!$E$27*Parametros!$C$41
A7: IVA no equipamento à taxa normal | B7: I_EQN | C7: =Inputs!$C$28*Parametros!$C$41 | D7: =Inputs!$D$28*Parametros!$C$41 | E7: =Inputs!$E$28*Parametros!$C$41
A8: IVA no equipamento à taxa reduzida | B8: I_EQR | C8: =Inputs!$C$29*Parametros!$C$42 | D8: =Inputs!$D$29*Parametros!$C$42 | E8: =Inputs!$E$29*Parametros!$C$42 | F8: Verbas 2.5 e 2.6 da Lista I do CIVA. A confirmar item a item contra o orçamento de equipamento — é a atenuante mais barata de obter e ninguém a verificou ainda.
A9: IVA no software | B9: I_SOFT | C9: =Inputs!$C$30*Parametros!$C$41 | D9: =Inputs!$D$30*Parametros!$C$41 | E9: =Inputs!$E$30*Parametros!$C$41
A10: Total de IVA suportado no investimento | B10: I_TOT | C10: =SUM($C$6:$C$9) | D10: =SUM($D$6:$D$9) | E10: =SUM($E$6:$E$9)
A11: Tratamento nas vias 1, 2 e 3 — atividade exclusivamente isenta
A12: IVA dedutível | B12: D_ISENTO | C12: =0 | D12: =0 | E12: =0 | F12: Art. 20.º n.º 1 CIVA a contrario: isenção do art. 9.º não confere direito à dedução.
A13: IVA perdido, convertido em custo do investimento | B13: P_ISENTO | C13: =$C$10 | D13: =$D$10 | E13: =$E$10 | F13: Este montante acresce ao custo de aquisição e é amortizado nas vias com contabilidade.
A14: Tratamento na via 4 — sujeito passivo misto
A15: Pro rata de dedução | B15: PRO_RATA | C15: =IF(Inputs!$C$46<=0,0,Inputs!$C$47/Inputs!$C$46) | D15: =IF(Inputs!$D$46<=0,0,Inputs!$D$47/Inputs!$D$46) | E15: =IF(Inputs!$E$46<=0,0,Inputs!$E$47/Inputs!$E$46) | F15: Art. 23.º n.º 4 CIVA: volume de negócios com direito a dedução sobre o total. Com FAT_TRIB a zero o pro rata é zero — só há dedução se o cônjuge faturar dentro da sociedade.
A16: % do investimento afeto exclusivamente à atividade tributada | B16: PCT_EXCL | C16: 0 | D16: 0 | E16: 0 | F16: Só relevante na afetação real. A preencher com base na planta do espaço e no orçamento de obras.
A17: IVA dedutível — método do pro rata | B17: D_PRORATA | C17: =$C$10*$C$15 | D17: =$D$10*$D$15 | E17: =$E$10*$E$15
A18: IVA dedutível — método da afetação real | B18: D_REAL | C18: =$C$10*$C$16+$C$10*(1-$C$16)*$C$15 | D18: =$D$10*$D$16+$D$10*(1-$D$16)*$D$15 | E18: =$E$10*$E$16+$E$10*(1-$E$16)*$E$15 | F18: Art. 23.º n.º 2 CIVA. Dedução integral na parte exclusivamente afeta a operações tributadas, pro rata nos custos comuns. Mais favorável, mas exige segregação documental permanente (ata, ponto 6).
A19: IVA recuperável na melhor hipótese | B19: D_MELHOR | C19: =MAX($C$17,$C$18) | D19: =MAX($D$17,$D$18) | E19: =MAX($E$17,$E$18)
A20: IVA perdido na via 4 | B20: P_MISTO | C20: =$C$10-$C$19 | D20: =$D$10-$D$19 | E20: =$E$10-$E$19
A21: Ganho de IVA atribuível à entrada do cônjuge | B21: GANHO | C21: =$C$13-$C$20 | D21: =$D$13-$D$20 | E21: =$E$13-$E$20 | F21: Comparar com o diferencial de IRS/IRC da folha Comparativo. A ata afirma que o efeito da transparência é 'materialmente superior' ao do IVA — esta linha é o teste dessa afirmação.
A22: Sensibilidade — elegibilidade para taxa reduzida
A23: % do equipamento que viesse a qualificar para a taxa reduzida | B23: SENS_PCT | C23: 0.3 | D23: 0.3 | E23: 0.3 | F23: Cenário de teste. Não é uma estimativa: substituir pela verificação item a item.
A24: Poupança de IVA nesse cenário | B24: SENS_GAN | C24: =Inputs!$C$28*$C$23*(Parametros!$C$41-Parametros!$C$42) | D24: =Inputs!$D$28*$D$23*(Parametros!$C$41-Parametros!$C$42) | E24: =Inputs!$E$28*$E$23*(Parametros!$C$41-Parametros!$C$42)
A25: IVA em custos correntes (anual, memória)
A26: Base dos custos correntes sujeitos a IVA | B26: C_CORR | C26: =Inputs!$C$22+Inputs!$C$24+Inputs!$C$25 | D26: =Inputs!$D$22+Inputs!$D$24+Inputs!$D$25 | E26: =Inputs!$E$22+Inputs!$E$24+Inputs!$E$25 | F26: Renda paga excluída: o arrendamento é isento salvo renúncia (art. 9.º n.º 29 CIVA). Honorários de fisioterapeutas excluídos: também isentos pelo art. 9.º n.º 1.
